Workbook

Sheet Control 233
A1: Atlas 2.0 · control de migración de 233 entradas | B1: Atlas 2.0 · control de migración de 233 entradas | C1: Atlas 2.0 · control de migración de 233 entradas | D1: Atlas 2.0 · control de migración de 233 entradas | E1: Atlas 2.0 · control de migración de 233 entradas | F1: Atlas 2.0 · control de migración de 233 entradas | G1: Atlas 2.0 · control de migración de 233 entradas | H1: Atlas 2.0 · control de migración de 233 entradas
A2: Plan editorial y técnico por lotes. No modifica el corpus público ni autoriza una integración en main. | B2: Plan editorial y técnico por lotes. No modifica el corpus público ni autoriza una integración en main. | C2: Plan editorial y técnico por lotes. No modifica el corpus público ni autoriza una integración en main. | D2: Plan editorial y técnico por lotes. No modifica el corpus público ni autoriza una integración en main. | E2: Plan editorial y técnico por lotes. No modifica el corpus público ni autoriza una integración en main. | F2: Plan editorial y técnico por lotes. No modifica el corpus público ni autoriza una integración en main. | G2: Plan editorial y técnico por lotes. No modifica el corpus público ni autoriza una integración en main. | H2: Plan editorial y técnico por lotes. No modifica el corpus público ni autoriza una integración en main.
A4: Indicador | B4: Valor | D4: Reglas de cierre | E4: Reglas de cierre | F4: Reglas de cierre | G4: Reglas de cierre | H4: Reglas de cierre
A5: Entradas fuente v1.15.0 | B5: =COUNTA('Plan 233'!$A$5:$A$237) -> 233 | D5: 1. La fuente pública permanece intacta durante toda la migración.
A6: Nodos efectivos proyectados | B6: =B5-COUNTIF('Plan 233'!$K$5:$K$237,"revisada_redireccion") -> 232 | D6: 2. Cada lote conserva f, l, tr, y y los identificadores heredados.
A7: Clasificaciones confirmadas (P00+A01+A02) | B7: 27 | D7: 3. Ninguna candidatura se vuelve confirmación sin fuente y fundamento.
A8: Redirecciones aprobadas (P00+A01+A02) | B8: 17 | D8: 4. Una relación se revisa cuando ambos extremos ya fueron revisados.
A9: Entradas listas para generar | B9: =COUNTIF('Plan 233'!$W$5:$W$237,"SÍ") -> 1 | D9: 5. Cada lote exige generador reproducible, validador, diff y aprobación.
A10: Entradas aún no listas | B10: =B5-B9 -> 232 | D10: 6. Cada lote ocupa un commit propio y puede revertirse sin tocar otros.
A11: Lotes totales | B11: 16 | D11: 7. C1, C2 y C5 no se rellenan para equilibrar cifras.
A12: Lotes cerrados | B12: 4 | D12: 8. La publicación solo se considera después de cerrar los 16 lotes, incluido T01.
A13: Relaciones fuente v1.15.0 | B13: =COUNTA('Plan relaciones'!$A$5:$A$592) -> 588
A14: Corroboradas en fuente | B14: =COUNTIF('Plan relaciones'!$H$5:$H$592,"corroborada") -> 382 | D14: Punto de partida comprobado | E14: Punto de partida comprobado | F14: Punto de partida comprobado | G14: Punto de partida comprobado | H14: Punto de partida comprobado
A15: Por corroborar en fuente | B15: =COUNTIF('Plan relaciones'!$H$5:$H$592,"por_corroborar") -> 206 | D15: v1.15.0: 233 entradas, 588 relaciones y 30 lugares.
A16: Corroboradas tras dictamen | B16: 362 | D16: P00, S01, A01 y A02 están cerrados como capas de transición reproducibles.
A17: Por corroborar tras dictamen | B17: 226 | D17: El parche conceptual fddd441 no altera el corpus público ni reabre esos lotes.
A18: Relaciones listas para generar | B18: 43 | D18: Siguiente acción: T01 sobre el campo tr; A03 queda detrás de T01. No cambiar a main.

Sheet Lotes
A1: Atlas 2.0 · dieciséis lotes revisables | B1: Atlas 2.0 · dieciséis lotes revisables | C1: Atlas 2.0 · dieciséis lotes revisables | D1: Atlas 2.0 · dieciséis lotes revisables | E1: Atlas 2.0 · dieciséis lotes revisables | F1: Atlas 2.0 · dieciséis lotes revisables | G1: Atlas 2.0 · dieciséis lotes revisables | H1: Atlas 2.0 · dieciséis lotes revisables | I1: Atlas 2.0 · dieciséis lotes revisables | J1: Atlas 2.0 · dieciséis lotes revisables | K1: Atlas 2.0 · dieciséis lotes revisables | L1: Atlas 2.0 · dieciséis lotes revisables | M1: Atlas 2.0 · dieciséis lotes revisables | N1: Atlas 2.0 · dieciséis lotes revisables
A2: Máximo 18 entradas por lote intelectual. T01 es un pase técnico transversal sobre las 233 entradas y no reclasifica corrientes. | B2: Máximo 18 entradas por lote intelectual. T01 es un pase técnico transversal sobre las 233 entradas y no reclasifica corrientes. | C2: Máximo 18 entradas por lote intelectual. T01 es un pase técnico transversal sobre las 233 entradas y no reclasifica corrientes. | D2: Máximo 18 entradas por lote intelectual. T01 es un pase técnico transversal sobre las 233 entradas y no reclasifica corrientes. | E2: Máximo 18 entradas por lote intelectual. T01 es un pase técnico transversal sobre las 233 entradas y no reclasifica corrientes. | F2: Máximo 18 entradas por lote intelectual. T01 es un pase técnico transversal sobre las 233 entradas y no reclasifica corrientes. | G2: Máximo 18 entradas por lote intelectual. T01 es un pase técnico transversal sobre las 233 entradas y no reclasifica corrientes. | H2: Máximo 18 entradas por lote intelectual. T01 es un pase técnico transversal sobre las 233 entradas y no reclasifica corrientes. | I2: Máximo 18 entradas por lote intelectual. T01 es un pase técnico transversal sobre las 233 entradas y no reclasifica corrientes. | J2: Máximo 18 entradas por lote intelectual. T01 es un pase técnico transversal sobre las 233 entradas y no reclasifica corrientes. | K2: Máximo 18 entradas por lote intelectual. T01 es un pase técnico transversal sobre las 233 entradas y no reclasifica corrientes. | L2: Máximo 18 entradas por lote intelectual. T01 es un pase técnico transversal sobre las 233 entradas y no reclasifica corrientes. | M2: Máximo 18 entradas por lote intelectual. T01 es un pase técnico transversal sobre las 233 entradas y no reclasifica corrientes. | N2: Máximo 18 entradas por lote intelectual. T01 es un pase técnico transversal sobre las 233 entradas y no reclasifica corrientes.
A4: Secuencia | B4: Lote | C4: Enfoque | D4: Criterio editorial | E4: Entradas | F4: Relaciones asignadas | G4: Internas | H4: Frontera | I4: Corroboradas iniciales | J4: Por corroborar iniciales | K4: Estado | L4: Dependencia | M4: Criterio de aceptación | N4: Reversión
A5: 1 | B5: P00 | C5: Piloto aprobado | D5: Diez casos representativos; ocho clasificaciones confirmadas, una redirección y un nodo compuesto que permanece pendiente. | E5: 10 | F5: 3 | G5: 3 | H5: 0 | I5: 2 | J5: 1 | K5: cerrado_capa_transicion | L5: — | M5: 100 % de entradas y relaciones asignadas con fuente/fundamento, aprobación académica, QA=pasa y validador con 0 errores y 0 advertencias. | N5: Commit propio; revertir únicamente ese commit y regenerar desde la fuente heredada.
A6: 2 | B6: S01 | C6: Bloqueos bibliográficos e identidad | D6: Resolver divisiones, referencias incompletas, correcciones de tipo y metadatos antes de ampliar la clasificación. | E6: 11 | F6: 12 | G6: 7 | H6: 5 | I6: 6 | J6: 6 | K6: cerrado_capa_transicion | L6: P00 | M6: 100 % de entradas y relaciones asignadas con fuente/fundamento, aprobación académica, QA=pasa y validador con 0 errores y 0 advertencias. | N6: Commit propio; revertir únicamente ese commit y regenerar desde la fuente heredada.
A7: 3 | B7: A01 | C7: Candidatura única · tramo 1 | D7: Confirmar o corregir la candidatura única mediante fuente y fundamento escrito. | E7: 18 | F7: 14 | G7: 7 | H7: 7 | I7: 13 | J7: 1 | K7: cerrado_capa_transicion | L7: S01 | M7: 100 % de entradas y relaciones asignadas con fuente/fundamento, aprobación académica, QA=pasa y validador con 0 errores y 0 advertencias. | N7: Commit propio; revertir únicamente ese commit y regenerar desde la fuente heredada.
A8: 4 | B8: A02 | C8: Candidatura única · tramo 2 | D8: Confirmar o corregir la candidatura única mediante fuente y fundamento escrito. | E8: 18 | F8: 14 | G8: 2 | H8: 12 | I8: 11 | J8: 3 | K8: cerrado_capa_transicion | L8: A01 | M8: 100 % de entradas y relaciones asignadas con fuente/fundamento, aprobación académica, QA=pasa y validador con 0 errores y 0 advertencias. | N8: Commit propio; revertir únicamente ese commit y regenerar desde la fuente heredada.
A9: 5 | B9: T01 | C9: Descomposición controlada del campo tr | D9: Conservar tr y separar lengua de publicación, orilla de producción, territorio estudiado y alcance comparativo. La extracción mecánica solo propone; ninguna propuesta se confirma sin revisión humana. | E9: 233 | F9: 0 | G9: 0 | H9: 0 | I9: 0 | J9: 0 | K9: siguiente | L9: A02 | M9: 233 valores originales conservados; 233 revisiones explícitas; ninguna lengua u orilla confirmada por inferencia; QA con 0 errores y aprobación académica. | N9: Commit propio; revertir solo T01. No escribir en datos-atlas.js/json ni alterar P00, S01, A01 o A02.
A10: 6 | B10: A03 | C10: Candidatura única · tramo 3 | D10: Confirmar o corregir la candidatura única mediante fuente y fundamento escrito. | E10: 18 | F10: 24 | G10: 8 | H10: 16 | I10: 18 | J10: 6 | K10: pendiente | L10: T01 | M10: 100 % de entradas y relaciones asignadas con fuente/fundamento, aprobación académica, QA=pasa y validador con 0 errores y 0 advertencias. | N10: Commit propio; revertir únicamente ese commit y regenerar desde la fuente heredada.
A11: 7 | B11: B01 | C11: Candidaturas múltiples · tramo 1 | D11: Leer para decidir qué corriente organiza el argumento; las coetiquetas solo orientan. | E11: 17 | F11: 42 | G11: 18 | H11: 24 | I11: 33 | J11: 9 | K11: pendiente | L11: A03 | M11: 100 % de entradas y relaciones asignadas con fuente/fundamento, aprobación académica, QA=pasa y validador con 0 errores y 0 advertencias. | N11: Commit propio; revertir únicamente ese commit y regenerar desde la fuente heredada.
A12: 8 | B12: B02 | C12: Candidaturas múltiples · tramo 2 | D12: Leer para decidir qué corriente organiza el argumento; las coetiquetas solo orientan. | E12: 16 | F12: 40 | G12: 7 | H12: 33 | I12: 23 | J12: 17 | K12: pendiente | L12: B01 | M12: 100 % de entradas y relaciones asignadas con fuente/fundamento, aprobación académica, QA=pasa y validador con 0 errores y 0 advertencias. | N12: Commit propio; revertir únicamente ese commit y regenerar desde la fuente heredada.
A13: 9 | B13: B03 | C13: Candidaturas múltiples · tramo 3 | D13: Leer para decidir qué corriente organiza el argumento; las coetiquetas solo orientan. | E13: 16 | F13: 40 | G13: 4 | H13: 36 | I13: 32 | J13: 8 | K13: pendiente | L13: B02 | M13: 100 % de entradas y relaciones asignadas con fuente/fundamento, aprobación académica, QA=pasa y validador con 0 errores y 0 advertencias. | N13: Commit propio; revertir únicamente ese commit y regenerar desde la fuente heredada.
A14: 10 | B14: B04 | C14: Candidaturas múltiples · tramo 4 | D14: Leer para decidir qué corriente organiza el argumento; las coetiquetas solo orientan. | E14: 16 | F14: 39 | G14: 6 | H14: 33 | I14: 17 | J14: 22 | K14: pendiente | L14: B03 | M14: 100 % de entradas y relaciones asignadas con fuente/fundamento, aprobación académica, QA=pasa y validador con 0 errores y 0 advertencias. | N14: Commit propio; revertir únicamente ese commit y regenerar desde la fuente heredada.
A15: 11 | B15: B05 | C15: Candidaturas múltiples · tramo 5 | D15: Leer para decidir qué corriente organiza el argumento; las coetiquetas solo orientan. | E15: 16 | F15: 41 | G15: 10 | H15: 31 | I15: 18 | J15: 23 | K15: pendiente | L15: B04 | M15: 100 % de entradas y relaciones asignadas con fuente/fundamento, aprobación académica, QA=pasa y validador con 0 errores y 0 advertencias. | N15: Commit propio; revertir únicamente ese commit y regenerar desde la fuente heredada.
A16: 12 | B16: C01 | C16: Colonialidad y candidatura · tramo 1 | D16: Distinguir invasión, régimen esclavista, administración imperial y persistencia contemporánea. | E16: 16 | F16: 64 | G16: 6 | H16: 58 | I16: 44 | J16: 20 | K16: pendiente | L16: B05 | M16: 100 % de entradas y relaciones asignadas con fuente/fundamento, aprobación académica, QA=pasa y validador con 0 errores y 0 advertencias. | N16: Commit propio; revertir únicamente ese commit y regenerar desde la fuente heredada.
... A20: 16 | B20: DE01 | C20: Sin destino derivable | D20: Lectura completa: colonialidad sola o etiquetas que pasan a marcas; queda prohibida la clasificación por título. | E20: 16 | F20: 78 | G20: 10 | H20: 68 | I20: 45 | J20: 33 | K20: pendiente | L20: C04 | M20: 100 % de entradas y relaciones asignadas con fuente/fundamento, aprobación académica, QA=pasa y validador con 0 errores y 0 advertencias. | N20: Commit propio; revertir únicamente ese commit y regenerar desde la fuente heredada.

Sheet Plan 233
A1: Atlas 2.0 · plan operativo de 233 entradas | B1: Atlas 2.0 · plan operativo de 233 entradas | C1: Atlas 2.0 · plan operativo de 233 entradas | D1: Atlas 2.0 · plan operativo de 233 entradas | E1: Atlas 2.0 · plan operativo de 233 entradas | F1: Atlas 2.0 · plan operativo de 233 entradas | G1: Atlas 2.0 · plan operativo de 233 entradas | H1: Atlas 2.0 · plan operativo de 233 entradas | I1: Atlas 2.0 · plan operativo de 233 entradas | J1: Atlas 2.0 · plan operativo de 233 entradas | K1: Atlas 2.0 · plan operativo de 233 entradas | L1: Atlas 2.0 · plan operativo de 233 entradas | M1: Atlas 2.0 · plan operativo de 233 entradas | N1: Atlas 2.0 · plan operativo de 233 entradas | O1: Atlas 2.0 · plan operativo de 233 entradas | P1: Atlas 2.0 · plan operativo de 233 entradas | Q1: Atlas 2.0 · plan operativo de 233 entradas | R1: Atlas 2.0 · plan operativo de 233 entradas | S1: Atlas 2.0 · plan operativo de 233 entradas | T1: Atlas 2.0 · plan operativo de 233 entradas | U1: Atlas 2.0 · plan operativo de 233 entradas | V1: Atlas 2.0 · plan operativo de 233 entradas | W1: Atlas 2.0 · plan operativo de 233 entradas | X1: Atlas 2.0 · plan operativo de 233 entradas
A2: Las columnas A–G conservan el contexto heredado. Las decisiones 2.0 empiezan en K y no se confirman automáticamente. | B2: Las columnas A–G conservan el contexto heredado. Las decisiones 2.0 empiezan en K y no se confirman automáticamente. | C2: Las columnas A–G conservan el contexto heredado. Las decisiones 2.0 empiezan en K y no se confirman automáticamente. | D2: Las columnas A–G conservan el contexto heredado. Las decisiones 2.0 empiezan en K y no se confirman automáticamente. | E2: Las columnas A–G conservan el contexto heredado. Las decisiones 2.0 empiezan en K y no se confirman automáticamente. | F2: Las columnas A–G conservan el contexto heredado. Las decisiones 2.0 empiezan en K y no se confirman automáticamente. | G2: Las columnas A–G conservan el contexto heredado. Las decisiones 2.0 empiezan en K y no se confirman automáticamente. | H2: Las columnas A–G conservan el contexto heredado. Las decisiones 2.0 empiezan en K y no se confirman automáticamente. | I2: Las columnas A–G conservan el contexto heredado. Las decisiones 2.0 empiezan en K y no se confirman automáticamente. | J2: Las columnas A–G conservan el contexto heredado. Las decisiones 2.0 empiezan en K y no se confirman automáticamente. | K2: Las columnas A–G conservan el contexto heredado. Las decisiones 2.0 empiezan en K y no se confirman automáticamente. | L2: Las columnas A–G conservan el contexto heredado. Las decisiones 2.0 empiezan en K y no se confirman automáticamente. | M2: Las columnas A–G conservan el contexto heredado. Las decisiones 2.0 empiezan en K y no se confirman automáticamente. | N2: Las columnas A–G conservan el contexto heredado. Las decisiones 2.0 empiezan en K y no se confirman automáticamente. | O2: Las columnas A–G conservan el contexto heredado. Las decisiones 2.0 empiezan en K y no se confirman automáticamente. | P2: Las columnas A–G conservan el contexto heredado. Las decisiones 2.0 empiezan en K y no se confirman automáticamente. | Q2: Las columnas A–G conservan el contexto heredado. Las decisiones 2.0 empiezan en K y no se confirman automáticamente. | R2: Las columnas A–G conservan el contexto heredado. Las decisiones 2.0 empiezan en K y no se confirman automáticamente. | S2: Las columnas A–G conservan el contexto heredado. Las decisiones 2.0 empiezan en K y no se confirman automáticamente. | T2: Las columnas A–G conservan el contexto heredado. Las decisiones 2.0 empiezan en K y no se confirman automáticamente. | U2: Las columnas A–G conservan el contexto heredado. Las decisiones 2.0 empiezan en K y no se confirman automáticamente. | V2: Las columnas A–G conservan el contexto heredado. Las decisiones 2.0 empiezan en K y no se confirman automáticamente. | W2: Las columnas A–G conservan el contexto heredado. Las decisiones 2.0 empiezan en K y no se confirman automáticamente. | X2: Las columnas A–G conservan el contexto heredado. Las decisiones 2.0 empiezan en K y no se confirman automáticamente.
A4: id | B4: Título | C4: Autoría | D4: Año heredado | E4: Estado de candidatura | F4: Corriente(s) candidata(s) | G4: Proceso | H4: Lote | I4: Orden | J4: Complejidad | K4: Estado editorial | L4: Corriente principal 2.0 | M4: Secundarias 2.0 | N4: Operaciones epistémicas | O4: Temporalidades | P4: Orillas / rutas | Q4: Fuente de decisión | R4: Fundamento | S4: Responsable | T4: Fecha revisión | U4: QA técnico | V4: Aprobación académica | W4: Listo para generar | X4: Pendientes / nota
A5: mintz | B5: Caribbean Transformations / Sweetness and Power | C5: Sidney W. Mintz | D5: 1974–85 | E5: A · candidatura preliminar única | F5: C4 · Postplantación, trabajo y desposesión | G5: división + migración | H5: P00 | I5: 1 | J5: piloto aprobado | K5: pendiente_revision_con_texto | O5: {"valor_heredado":"1974–85","publicacion":null,"requiere_revision":true} | R5: El nodo reúne dos obras con argumentos diferentes; no se confirma una corriente única hasta revisar cada componente. | S5: Dirección académica de Pensamiento Caribe | T5: 46242 | U5: pasa | V5: aprobada | W5: =IF(OR(AND(K5="confirmada",L5<>"",N5<>"",O5<>"",P5<>"",Q5<>"",R5<>"",S5<>"",T5<>"",U5="pasa",V5="aprobada",OR(X5="",X5="—")),AND(K5="revisada_redireccion",Q5<>"",R5<>"",S5<>"",T5<>"",U5="pasa",V5="aprobada",OR(X5="",X5="—"))),"SÍ","NO") -> NO | X5: corriente_por_componente; mecanismo_capitalismo_racial; operaciones; orillas
A6: trouillot | B6: The Caribbean Region: An Open Frontier | C6: Michel-Rolph Trouillot | D6: 1992 | E6: C · reparto de colonialidad y candidaturas | F6: C9 · Memorias, espiritualidades y archivos vivos | G6: reclasificación | H6: C04 | I6: 1 | J6: reparto de colonialidad | K6: sin_iniciar | U6: pendiente | V6: pendiente | W6: =IF(OR(AND(K6="confirmada",L6<>"",N6<>"",O6<>"",P6<>"",Q6<>"",R6<>"",S6<>"",T6<>"",U6="pasa",V6="aprobada",OR(X6="",X6="—")),AND(K6="revisada_redireccion",Q6<>"",R6<>"",S6<>"",T6<>"",U6="pasa",V6="aprobada",OR(X6="",X6="—"))),"SÍ","NO") -> NO
A7: casimir | B7: The Haitians: A Decolonial History | C7: Jean Casimir | D7: 2020 | E7: C · reparto de colonialidad y candidaturas | F7: C4 · Postplantación, trabajo y desposesión | G7: reclasificación | H7: C01 | I7: 10 | J7: reparto de colonialidad | K7: sin_iniciar | U7: pendiente | V7: pendiente | W7: =IF(OR(AND(K7="confirmada",L7<>"",N7<>"",O7<>"",P7<>"",Q7<>"",R7<>"",S7<>"",T7<>"",U7="pasa",V7="aprobada",OR(X7="",X7="—")),AND(K7="revisada_redireccion",Q7<>"",R7<>"",S7<>"",T7<>"",U7="pasa",V7="aprobada",OR(X7="",X7="—"))),"SÍ","NO") -> NO
A8: price | B8: Maroon Societies | C8: Richard Price (ed.) | D8: 1973 | E8: B · varias candidaturas preliminares | F8: C3 · Fugas, cimarronajes y emancipaciones | C9 · Memorias, espiritualidades y archivos vivos | G8: reclasificación | H8: P00 | I8: 2 | J8: piloto aprobado | K8: confirmada | L8: fugas_cimarronajes_emancipaciones | N8: reconstruir un archivo; comparar orillas | O8: {"publicacion":{"valor":1973,"era":"EC","precision":"exacta"}} | Q8: https://search.worldcat.org/oclc/805137?tab=details https://www.press.jhu.edu/books/title/1940/maroon-societies | R8: El volumen organiza una comparación hemisférica de comunidades cimarronas y combina fuentes históricas y estudios antropológicos. | S8: Dirección académica de Pensamiento Caribe | T8: 46242 | U8: pasa | V8: aprobada | W8: =IF(OR(AND(K8="confirmada",L8<>"",N8<>"",O8<>"",P8<>"",Q8<>"",R8<>"",S8<>"",T8<>"",U8="pasa",V8="aprobada",OR(X8="",X8="—")),AND(K8="revisada_redireccion",Q8<>"",R8<>"",S8<>"",T8<>"",U8="pasa",V8="aprobada",OR(X8="",X8="—"))),"SÍ","NO") -> NO | X8: orillas
A9: fouchard | B9: Les marrons de la liberté | C9: Jean Fouchard | D9: 1972 | E9: B · varias candidaturas preliminares | F9: C3 · Fugas, cimarronajes y emancipaciones | C7 · Soberanías, fronteras y ocupaciones | G9: reclasificación | H9: B01 | I9: 17 | J9: elección entre candidaturas | K9: sin_iniciar | U9: pendiente | V9: pendiente | W9: =IF(OR(AND(K9="confirmada",L9<>"",N9<>"",O9<>"",P9<>"",Q9<>"",R9<>"",S9<>"",T9<>"",U9="pasa",V9="aprobada",OR(X9="",X9="—")),AND(K9="revisada_redireccion",Q9<>"",R9<>"",S9<>"",T9<>"",U9="pasa",V9="aprobada",OR(X9="",X9="—"))),"SÍ","NO") -> NO
A10: roberts | B10: Freedom as Marronage | C10: Neil Roberts | D10: 2015 | E10: B · varias candidaturas preliminares | F10: C3 · Fugas, cimarronajes y emancipaciones | C7 · Soberanías, fronteras y ocupaciones | G10: reclasificación | H10: B01 | I10: 16 | J10: elección entre candidaturas | K10: sin_iniciar | U10: pendiente | V10: pendiente | W10: =IF(OR(AND(K10="confirmada",L10<>"",N10<>"",O10<>"",P10<>"",Q10<>"",R10<>"",S10<>"",T10<>"",U10="pasa",V10="aprobada",OR(X10="",X10="—")),AND(K10="revisada_redireccion",Q10<>"",R10<>"",S10<>"",T10<>"",U10="pasa",V10="aprobada",OR(X10="",X10="—"))),"SÍ","NO") -> NO
A11: totumo | B11: Los acuerdos y la idealización del palenque en la provincia de Cartagena: el caso del Totumo (1714-1767) | C11: Dolcey Romero Jaramillo | E11: B · varias candidaturas preliminares | F11: C3 · Fugas, cimarronajes y emancipaciones | C9 · Memorias, espiritualidades y archivos vivos | G11: corrección bibliográfica + reclasificación | H11: P00 | I11: 3 | J11: piloto aprobado | K11: confirmada | L11: fugas_cimarronajes_emancipaciones | N11: reconstruir un archivo; confrontar una categoría | O11: {"publicacion":{"valor":2020,"era":"EC","precision":"exacta"},"periodo_estudiado":{"inicio":{"valor":1714,"era":"EC","precision":"exacta"},"fin":{"valor":1767,"era":"EC","precision":"exacta"}}} | Q11: https://revistas.uniatlantico.edu.co/index.php/Historia_Caribe/article/view/2403 https://doi.org/10.15648/hc.37.2020.9 | R11: El artículo reconstruye acuerdos entre cimarrones y autoridades coloniales y cuestiona la idealización del palenque como libertad absoluta. | S11: Dirección académica de Pensamiento Caribe | T11: 46242 | U11: pasa | V11: aprobada | W11: =IF(OR(AND(K11="confirmada",L11<>"",N11<>"",O11<>"",P11<>"",Q11<>"",R11<>"",S11<>"",T11<>"",U11="pasa",V11="aprobada",OR(X11="",X11="—")),AND(K11="revisada_redireccion",Q11<>"",R11<>"",S11<>"",T11<>"",U11="pasa",V11="aprobada",OR(X11="",X11="—"))),"SÍ","NO") -> NO | X11: orillas
A12: ortiz | B12: Contrapunteo cubano / Transculturación | C12: Fernando Ortiz | D12: 1940 | E12: B · varias candidaturas preliminares | F12: C8 · Creolizaciones, traducciones y opacidades | C4 · Postplantación, trabajo y desposesión | G12: división + reclasificación | H12: S01 | I12: 3 | J12: bloqueo editorial | K12: sin_iniciar | U12: pendiente | V12: pendiente | W12: =IF(OR(AND(K12="confirmada",L12<>"",N12<>"",O12<>"",P12<>"",Q12<>"",R12<>"",S12<>"",T12<>"",U12="pasa",V12="aprobada",OR(X12="",X12="—")),AND(K12="revisada_redireccion",Q12<>"",R12<>"",S12<>"",T12<>"",U12="pasa",V12="aprobada",OR(X12="",X12="—"))),"SÍ","NO") -> NO
A13: glissant | B13: Poétique de la Relation / Le discours antillais | C13: Édouard Glissant | D13: 1981–90 | E13: C · reparto de colonialidad y candidaturas | F13: C8 · Creolizaciones, traducciones y opacidades | G13: división + reclasificación | H13: S01 | I13: 7 | J13: bloqueo editorial | K13: sin_iniciar | U13: pendiente | V13: pendiente | W13: =IF(OR(AND(K13="confirmada",L13<>"",N13<>"",O13<>"",P13<>"",Q13<>"",R13<>"",S13<>"",T13<>"",U13="pasa",V13="aprobada",OR(X13="",X13="—")),AND(K13="revisada_redireccion",Q13<>"",R13<>"",S13<>"",T13<>"",U13="pasa",V13="aprobada",OR(X13="",X13="—"))),"SÍ","NO") -> NO
A14: brathwaite | B14: Nation Language / Tidalectics | C14: Kamau Brathwaite | D14: 1984 | E14: B · varias candidaturas preliminares | F14: C8 · Creolizaciones, traducciones y opacidades | C9 · Memorias, espiritualidades y archivos vivos | G14: división + reclasificación | H14: S01 | I14: 5 | J14: bloqueo editorial | K14: sin_iniciar | U14: pendiente | V14: pendiente | W14: =IF(OR(AND(K14="confirmada",L14<>"",N14<>"",O14<>"",P14<>"",Q14<>"",R14<>"",S14<>"",T14<>"",U14="pasa",V14="aprobada",OR(X14="",X14="—")),AND(K14="revisada_redireccion",Q14<>"",R14<>"",S14<>"",T14<>"",U14="pasa",V14="aprobada",OR(X14="",X14="—"))),"SÍ","NO") -> NO
A15: creolite | B15: Éloge de la créolité | C15: Bernabé, Chamoiseau, Confiant | D15: 1989 | E15: A · candidatura preliminar única | F15: C8 · Creolizaciones, traducciones y opacidades | G15: migración | H15: A03 | I15: 8 | J15: confirmación de candidatura única | K15: sin_iniciar | U15: pendiente | V15: pendiente | W15: =IF(OR(AND(K15="confirmada",L15<>"",N15<>"",O15<>"",P15<>"",Q15<>"",R15<>"",S15<>"",T15<>"",U15="pasa",V15="aprobada",OR(X15="",X15="—")),AND(K15="revisada_redireccion",Q15<>"",R15<>"",S15<>"",T15<>"",U15="pasa",V15="aprobada",OR(X15="",X15="—"))),"SÍ","NO") -> NO
A16: monahan | B16: Creolizing Practices of Freedom: Recognition and Dissonance / The Creolizing Subject: Race, Reason, and the Politics of Purity | C16: Michael Monahan | D16: 2011–23 | E16: C · reparto de colonialidad y candidaturas | F16: C8 · Creolizaciones, traducciones y opacidades | G16: división + reclasificación | H16: S01 | I16: 6 | J16: bloqueo editorial | K16: sin_iniciar | U16: pendiente | V16: pendiente | W16: =IF(OR(AND(K16="confirmada",L16<>"",N16<>"",O16<>"",P16<>"",Q16<>"",R16<>"",S16<>"",T16<>"",U16="pasa",V16="aprobada",OR(X16="",X16="—")),AND(K16="revisada_redireccion",Q16<>"",R16<>"",S16<>"",T16<>"",U16="pasa",V16="aprobada",OR(X16="",X16="—"))),"SÍ","NO") -> NO
A17: vete | B17: The Caribbean Oral Tradition | C17: Hanétha Vété-Congolo (ed.) | D17: 2016 | E17: B · varias candidaturas preliminares | F17: C8 · Creolizaciones, traducciones y opacidades | C9 · Memorias, espiritualidades y archivos vivos | G17: reclasificación | H17: B04 | I17: 14 | J17: elección entre candidaturas | K17: sin_iniciar | U17: pendiente | V17: pendiente | W17: =IF(OR(AND(K17="confirmada",L17<>"",N17<>"",O17<>"",P17<>"",Q17<>"",R17<>"",S17<>"",T17<>"",U17="pasa",V17="aprobada",OR(X17="",X17="—")),AND(K17="revisada_redireccion",Q17<>"",R17<>"",S17<>"",T17<>"",U17="pasa",V17="aprobada",OR(X17="",X17="—"))),"SÍ","NO") -> NO
A18: chande | B18: Sonoridades del Chandé en el Caribe seco | C18: borrador / archivo | E18: B · varias candidaturas preliminares | F18: C8 · Creolizaciones, traducciones y opacidades | C9 · Memorias, espiritualidades y archivos vivos | G18: corrección bibliográfica + reclasificación | H18: P00 | I18: 4 | J18: piloto aprobado | K18: confirmada | L18: memorias_espiritualidades_archivos_vivos | M18: creolizaciones_traducciones_opacidades | N18: producir etnografía; escuchar; preservar una memoria; documentar una práctica; teorizar | O18: {"publicacion":{"valor":2016,"era":"EC","precision":"exacta"}} | P18: orillas: La Loma, El Paso, Cesar [territorio estudiado] | Q18: https://dialnet.unirioja.es/descarga/articulo/5888296.pdf https://doi.org/10.15648/cl.24.2016.6 | R18: El texto comprende el Chandé como pensamiento, saber y memoria mediante diálogo comunitario y respeto por el silencio de sabedoras y sabedores. | S18: Dirección académica de Pensamiento Caribe | T18: 46242 | U18: pasa | V18: aprobada | W18: =IF(OR(AND(K18="confirmada",L18<>"",N18<>"",O18<>"",P18<>"",Q18<>"",R18<>"",S18<>"",T18<>"",U18="pasa",V18="aprobada",OR(X18="",X18="—")),AND(K18="revisada_redireccion",Q18<>"",R18<>"",S18<>"",T18<>"",U18="pasa",V18="aprobada",OR(X18="",X18="—"))),"SÍ","NO") -> NO | X18: fechas_del_trabajo_de_campo; duracion_historica; coordenadas_orilla
A19: quintero | B19: Cuerpo y cultura: las músicas «mulatas» y la subversión del baile | C19: Ángel Quintero Rivera | D19: 2009 | E19: B · varias candidaturas preliminares | F19: C8 · Creolizaciones, traducciones y opacidades | C3 · Fugas, cimarronajes y emancipaciones | G19: reclasificación | H19: B03 | I19: 16 | J19: elección entre candidaturas | K19: sin_iniciar | U19: pendiente | V19: pendiente | W19: =IF(OR(AND(K19="confirmada",L19<>"",N19<>"",O19<>"",P19<>"",Q19<>"",R19<>"",S19<>"",T19<>"",U19="pasa",V19="aprobada",OR(X19="",X19="—")),AND(K19="revisada_redireccion",Q19<>"",R19<>"",S19<>"",T19<>"",U19="pasa",V19="aprobada",OR(X19="",X19="—"))),"SÍ","NO") -> NO
A20: perezmorales | B20: Cartagena's Privateers | C20: Edgardo Pérez Morales | D20: 2018 | E20: E · sin correspondencia directa en la taxonomía anterior | G20: reclasificación | H20: DE01 | I20: 15 | J20: sin correspondencia directa | K20: sin_iniciar | U20: pendiente | V20: pendiente | W20: =IF(OR(AND(K20="confirmada",L20<>"",N20<>"",O20<>"",P20<>"",Q20<>"",R20<>"",S20<>"",T20<>"",U20="pasa",V20="aprobada",OR(X20="",X20="—")),AND(K20="revisada_redireccion",Q20<>"",R20<>"",S20<>"",T20<>"",U20="pasa",V20="aprobada",OR(X20="",X20="—"))),"SÍ","NO") -> NO
A21: sherwood | B21: After Abolition: Britain and the Slave Trade | C21: Marika Sherwood | D21: 2007 | E21: E · sin correspondencia directa en la taxonomía anterior | G21: reclasificación | H21: DE01 | I21: 6 | J21: sin correspondencia directa | K21: sin_iniciar | U21: pendiente | V21: pendiente | W21: =IF(OR(AND(K21="confirmada",L21<>"",N21<>"",O21<>"",P21<>"",Q21<>"",R21<>"",S21<>"",T21<>"",U21="pasa",V21="aprobada",OR(X21="",X21="—")),AND(K21="revisada_redireccion",Q21<>"",R21<>"",S21<>"",T21<>"",U21="pasa",V21="aprobada",OR(X21="",X21="—"))),"SÍ","NO") -> NO
A22: cabrera | B22: El Monte | C22: Lydia Cabrera | D22: 1954 | E22: B · varias candidaturas preliminares | F22: C9 · Memorias, espiritualidades y archivos vivos | C8 · Creolizaciones, traducciones y opacidades | G22: reclasificación | H22: B05 | I22: 10 | J22: elección entre candidaturas | K22: sin_iniciar | U22: pendiente | V22: pendiente | W22: =IF(OR(AND(K22="confirmada",L22<>"",N22<>"",O22<>"",P22<>"",Q22<>"",R22<>"",S22<>"",T22<>"",U22="pasa",V22="aprobada",OR(X22="",X22="—")),AND(K22="revisada_redireccion",Q22<>"",R22<>"",S22<>"",T22<>"",U22="pasa",V22="aprobada",OR(X22="",X22="—"))),"SÍ","NO") -> NO
A23: tambu | B23: Tambú: Curaçao's African-Caribbean Ritual | C23: Nanette de Jong | D23: 2012 | E23: B · varias candidaturas preliminares | F23: C9 · Memorias, espiritualidades y archivos vivos | C8 · Creolizaciones, traducciones y opacidades | G23: reclasificación | H23: B05 | I23: 15 | J23: elección entre candidaturas | K23: sin_iniciar | U23: pendiente | V23: pendiente | W23: =IF(OR(AND(K23="confirmada",L23<>"",N23<>"",O23<>"",P23<>"",Q23<>"",R23<>"",S23<>"",T23<>"",U23="pasa",V23="aprobada",OR(X23="",X23="—")),AND(K23="revisada_redireccion",Q23<>"",R23<>"",S23<>"",T23<>"",U23="pasa",V23="aprobada",OR(X23="",X23="—"))),"SÍ","NO") -> NO
A24: bonilla | B24: Non-Sovereign Futures | C24: Yarimar Bonilla | D24: 2015 | E24: C · reparto de colonialidad y candidaturas | F24: C7 · Soberanías, fronteras y ocupaciones | G24: reclasificación | H24: C02 | I24: 13 | J24: reparto de colonialidad | K24: sin_iniciar | U24: pendiente | V24: pendiente | W24: =IF(OR(AND(K24="confirmada",L24<>"",N24<>"",O24<>"",P24<>"",Q24<>"",R24<>"",S24<>"",T24<>"",U24="pasa",V24="aprobada",OR(X24="",X24="—")),AND(K24="revisada_redireccion",Q24<>"",R24<>"",S24<>"",T24<>"",U24="pasa",V24="aprobada",OR(X24="",X24="—"))),"SÍ","NO") -> NO
A25: lindskoog | B25: Detain and Punish: Haitian Refugees | C25: Carl Lindskoog | D25: 2018 | E25: A · candidatura preliminar única | F25: C7 · Soberanías, fronteras y ocupaciones | G25: migración | H25: A03 | I25: 5 | J25: confirmación de candidatura única | K25: sin_iniciar | U25: pendiente | V25: pendiente | W25: =IF(OR(AND(K25="confirmada",L25<>"",N25<>"",O25<>"",P25<>"",Q25<>"",R25<>"",S25<>"",T25<>"",U25="pasa",V25="aprobada",OR(X25="",X25="—")),AND(K25="revisada_redireccion",Q25<>"",R25<>"",S25<>"",T25<>"",U25="pasa",V25="aprobada",OR(X25="",X25="—"))),"SÍ","NO") -> NO
A26: ferdinand | B26: Une écologie décoloniale | C26: Malcom Ferdinand | D26: 2019 | E26: C · reparto de colonialidad y candidaturas | F26: C6 · Huracanes, ecologías y materialidades vivas | G26: reclasificación | H26: C01 | I26: 16 | J26: reparto de colonialidad | K26: sin_iniciar | U26: pendiente | V26: pendiente | W26: =IF(OR(AND(K26="confirmada",L26<>"",N26<>"",O26<>"",P26<>"",Q26<>"",R26<>"",S26<>"",T26<>"",U26="pasa",V26="aprobada",OR(X26="",X26="—")),AND(K26="revisada_redireccion",Q26<>"",R26<>"",S26<>"",T26<>"",U26="pasa",V26="aprobada",OR(X26="",X26="—"))),"SÍ","NO") -> NO
A27: beyondsun | B27: Beyond Sun and Sand | C27: Baver & Lynch (eds.) | D27: 2006 | E27: A · candidatura preliminar única | F27: C6 · Huracanes, ecologías y materialidades vivas | G27: migración | H27: A02 | I27: 6 | J27: confirmación de candidatura única | K27: sin_iniciar | U27: pendiente | V27: pendiente | W27: =IF(OR(AND(K27="confirmada",L27<>"",N27<>"",O27<>"",P27<>"",Q27<>"",R27<>"",S27<>"",T27<>"",U27="pasa",V27="aprobada",OR(X27="",X27="—")),AND(K27="revisada_redireccion",Q27<>"",R27<>"",S27<>"",T27<>"",U27="pasa",V27="aprobada",OR(X27="",X27="—"))),"SÍ","NO") -> NO
A28: aftershocks | B28: Aftershocks of Disaster (huracán María) | C28: Bonilla & LeBrón (eds.) | D28: 2019 | E28: B · varias candidaturas preliminares | F28: C6 · Huracanes, ecologías y materialidades vivas | C7 · Soberanías, fronteras y ocupaciones | G28: reclasificación | H28: B03 | I28: 2 | J28: elección entre candidaturas | K28: sin_iniciar | U28: pendiente | V28: pendiente | W28: =IF(OR(AND(K28="confirmada",L28<>"",N28<>"",O28<>"",P28<>"",Q28<>"",R28<>"",S28<>"",T28<>"",U28="pasa",V28="aprobada",OR(X28="",X28="—")),AND(K28="revisada_redireccion",Q28<>"",R28<>"",S28<>"",T28<>"",U28="pasa",V28="aprobada",OR(X28="",X28="—"))),"SÍ","NO") -> NO
A29: rodney | B29: How Europe Underdeveloped Africa | C29: Walter Rodney | D29: 1972 | E29: D · reparto de colonialidad | G29: reclasificación | H29: DE01 | I29: 2 | J29: colonialidad sin destino derivable | K29: sin_iniciar | U29: pendiente | V29: pendiente | W29: =IF(OR(AND(K29="confirmada",L29<>"",N29<>"",O29<>"",P29<>"",Q29<>"",R29<>"",S29<>"",T29<>"",U29="pasa",V29="aprobada",OR(X29="",X29="—")),AND(K29="revisada_redireccion",Q29<>"",R29<>"",S29<>"",T29<>"",U29="pasa",V29="aprobada",OR(X29="",X29="—"))),"SÍ","NO") -> NO
A30: araujo | B30: Reparations for Slavery and the Slave Trade: A Transnational and Comparative History | C30: Ana Lucia Araujo | D30: 2017 | E30: A · candidatura preliminar única | F30: C9 · Memorias, espiritualidades y archivos vivos | G30: migración | H30: A03 | I30: 12 | J30: confirmación de candidatura única | K30: sin_iniciar | U30: pendiente | V30: pendiente | W30: =IF(OR(AND(K30="confirmada",L30<>"",N30<>"",O30<>"",P30<>"",Q30<>"",R30<>"",S30<>"",T30<>"",U30="pasa",V30="aprobada",OR(X30="",X30="—")),AND(K30="revisada_redireccion",Q30<>"",R30<>"",S30<>"",T30<>"",U30="pasa",V30="aprobada",OR(X30="",X30="—"))),"SÍ","NO") -> NO
A31: manoalzada | B31: A mano alzada: diáspora intelectual afrocolombiana | C31: archivo | D31: 2013 | E31: B · varias candidaturas preliminares | F31: C9 · Memorias, espiritualidades y archivos vivos | C7 · Soberanías, fronteras y ocupaciones | G31: corrección bibliográfica + reclasificación | H31: S01 | I31: 9 | J31: bloqueo editorial | K31: sin_iniciar | U31: pendiente | V31: pendiente | W31: =IF(OR(AND(K31="confirmada",L31<>"",N31<>"",O31<>"",P31<>"",Q31<>"",R31<>"",S31<>"",T31<>"",U31="pasa",V31="aprobada",OR(X31="",X31="—")),AND(K31="revisada_redireccion",Q31<>"",R31<>"",S31<>"",T31<>"",U31="pasa",V31="aprobada",OR(X31="",X31="—"))),"SÍ","NO") -> NO
A32: gudynas | B32: Extractivismos | C32: Eduardo Gudynas | D32: 2015 | E32: A · candidatura preliminar única | F32: C6 · Huracanes, ecologías y materialidades vivas | G32: migración | H32: A02 | I32: 5 | J32: confirmación de candidatura única | K32: sin_iniciar | U32: pendiente | V32: pendiente | W32: =IF(OR(AND(K32="confirmada",L32<>"",N32<>"",O32<>"",P32<>"",Q32<>"",R32<>"",S32<>"",T32<>"",U32="pasa",V32="aprobada",OR(X32="",X32="—")),AND(K32="revisada_redireccion",Q32<>"",R32<>"",S32<>"",T32<>"",U32="pasa",V32="aprobada",OR(X32="",X32="—"))),"SÍ","NO") -> NO
A33: esquiva | B33: La esquiva promesa de desarrollo | C33: archivo | E33: E · sin correspondencia directa en la taxonomía anterior | G33: corrección bibliográfica + reclasificación | H33: S01 | I33: 11 | J33: bloqueo editorial | K33: sin_iniciar | U33: pendiente | V33: pendiente | W33: =IF(OR(AND(K33="confirmada",L33<>"",N33<>"",O33<>"",P33<>"",Q33<>"",R33<>"",S33<>"",T33<>"",U33="pasa",V33="aprobada",OR(X33="",X33="—")),AND(K33="revisada_redireccion",Q33<>"",R33<>"",S33<>"",T33<>"",U33="pasa",V33="aprobada",OR(X33="",X33="—"))),"SÍ","NO") -> NO
A34: workercane | B34: Worker in the Cane: A Puerto Rican Life History | C34: Sidney W. Mintz | D34: 1960 | E34: A · candidatura preliminar única | F34: C4 · Postplantación, trabajo y desposesión | G34: migración | H34: A02 | I34: 2 | J34: confirmación de candidatura única | K34: sin_iniciar | U34: pendiente | V34: pendiente | W34: =IF(OR(AND(K34="confirmada",L34<>"",N34<>"",O34<>"",P34<>"",Q34<>"",R34<>"",S34<>"",T34<>"",U34="pasa",V34="aprobada",OR(X34="",X34="—")),AND(K34="revisada_redireccion",Q34<>"",R34<>"",S34<>"",T34<>"",U34="pasa",V34="aprobada",OR(X34="",X34="—"))),"SÍ","NO") -> NO
A35: steward | B35: The People of Puerto Rico: A Study in Social Anthropology | C35: Julian Steward et al. (con Mintz, Wolf, Padilla Seda) | D35: 1956 | E35: A · candidatura preliminar única | F35: C4 · Postplantación, trabajo y desposesión | G35: fusión + migración | H35: P00 | I35: 5 | J35: piloto aprobado | K35: confirmada | L35: postplantacion_trabajo_desposesion | N35: producir etnografía; comparar orillas; teorizar | O35: {"publicacion":{"valor":1956,"era":"EC","precision":"exacta"}} | Q35: https://eric.ed.gov/?id=ED019306 https://files.archon.library.illinois.edu/uasfa/1502021.pdf | R35: La obra compara subculturas puertorriqueñas configuradas por entornos y regímenes económicos locales; el identificador más antiguo conserva los enlaces citables. | S35: Dirección académica de Pensamiento Caribe | T35: 46242 | U35: pasa | V35: aprobada | W35: =IF(OR(AND(K35="confirmada",L35<>"",N35<>"",O35<>"",P35<>"",Q35<>"",R35<>"",S35<>"",T35<>"",U35="pasa",V35="aprobada",OR(X35="",X35="—")),AND(K35="revisada_redireccion",Q35<>"",R35<>"",S35<>"",T35<>"",U35="pasa",V35="aprobada",OR(X35="",X35="—"))),"SÍ","NO") -> NO | X35: orillas
A36: olwigstjohn | B36: Cultural Adaptation and Resistance on St. John | C36: Karen Fog Olwig | D36: 1985 | E36: B · varias candidaturas preliminares | F36: C4 · Postplantación, trabajo y desposesión | C9 · Memorias, espiritualidades y archivos vivos | G36: reclasificación | H36: B02 | I36: 16 | J36: elección entre candidaturas | K36: sin_iniciar | U36: pendiente | V36: pendiente | W36: =IF(OR(AND(K36="confirmada",L36<>"",N36<>"",O36<>"",P36<>"",Q36<>"",R36<>"",S36<>"",T36<>"",U36="pasa",V36="aprobada",OR(X36="",X36="—")),AND(K36="revisada_redireccion",Q36<>"",R36<>"",S36<>"",T36<>"",U36="pasa",V36="aprobada",OR(X36="",X36="—"))),"SÍ","NO") -> NO
A37: hagedorn | B37: Divine Utterances: The Performance of Afro-Cuban Santería | C37: Katherine J. Hagedorn | D37: 2001 | E37: B · varias candidaturas preliminares | F37: C9 · Memorias, espiritualidades y archivos vivos | C8 · Creolizaciones, traducciones y opacidades | G37: reclasificación | H37: B05 | I37: 9 | J37: elección entre candidaturas | K37: sin_iniciar | U37: pendiente | V37: pendiente | W37: =IF(OR(AND(K37="confirmada",L37<>"",N37<>"",O37<>"",P37<>"",Q37<>"",R37<>"",S37<>"",T37<>"",U37="pasa",V37="aprobada",OR(X37="",X37="—")),AND(K37="revisada_redireccion",Q37<>"",R37<>"",S37<>"",T37<>"",U37="pasa",V37="aprobada",OR(X37="",X37="—"))),"SÍ","NO") -> NO
A38: pricefirst | B38: First-Time: The Historical Vision of an Afro-American People | C38: Richard Price | D38: 1983 | E38: B · varias candidaturas preliminares | F38: C3 · Fugas, cimarronajes y emancipaciones | C9 · Memorias, espiritualidades y archivos vivos | G38: reclasificación | H38: B02 | I38: 3 | J38: elección entre candidaturas | K38: sin_iniciar | U38: pendiente | V38: pendiente | W38: =IF(OR(AND(K38="confirmada",L38<>"",N38<>"",O38<>"",P38<>"",Q38<>"",R38<>"",S38<>"",T38<>"",U38="pasa",V38="aprobada",OR(X38="",X38="—")),AND(K38="revisada_redireccion",Q38<>"",R38<>"",S38<>"",T38<>"",U38="pasa",V38="aprobada",OR(X38="",X38="—"))),"SÍ","NO") -> NO
A39: dunham | B39: Island Possessed | C39: Katherine Dunham | D39: 1969 | E39: B · varias candidaturas preliminares | F39: C9 · Memorias, espiritualidades y archivos vivos | C8 · Creolizaciones, traducciones y opacidades | G39: reclasificación | H39: B05 | I39: 11 | J39: elección entre candidaturas | K39: sin_iniciar | U39: pendiente | V39: pendiente | W39: =IF(OR(AND(K39="confirmada",L39<>"",N39<>"",O39<>"",P39<>"",Q39<>"",R39<>"",S39<>"",T39<>"",U39="pasa",V39="aprobada",OR(X39="",X39="—")),AND(K39="revisada_redireccion",Q39<>"",R39<>"",S39<>"",T39<>"",U39="pasa",V39="aprobada",OR(X39="",X39="—"))),"SÍ","NO") -> NO
A40: friedemannlengua | B40: Lengua y sociedad en el Palenque de San Basilio | C40: Carlos Patiño Rosselli & Nina S. de Friedemann | D40: 1983 | E40: B · varias candidaturas preliminares | F40: C8 · Creolizaciones, traducciones y opacidades | C3 · Fugas, cimarronajes y emancipaciones | G40: reclasificación | H40: B04 | I40: 1 | J40: elección entre candidaturas | K40: sin_iniciar | U40: pendiente | V40: pendiente | W40: =IF(OR(AND(K40="confirmada",L40<>"",N40<>"",O40<>"",P40<>"",Q40<>"",R40<>"",S40<>"",T40<>"",U40="pasa",V40="aprobada",OR(X40="",X40="—")),AND(K40="revisada_redireccion",Q40<>"",R40<>"",S40<>"",T40<>"",U40="pasa",V40="aprobada",OR(X40="",X40="—"))),"SÍ","NO") -> NO
A41: mamalola | B41: Mama Lola: A Vodou Priestess in Brooklyn | C41: Karen McCarthy Brown | D41: 1991 | E41: B · varias candidaturas preliminares | F41: C9 · Memorias, espiritualidades y archivos vivos | C8 · Creolizaciones, traducciones y opacidades | G41: reclasificación | H41: B05 | I41: 13 | J41: elección entre candidaturas | K41: sin_iniciar | U41: pendiente | V41: pendiente | W41: =IF(OR(AND(K41="confirmada",L41<>"",N41<>"",O41<>"",P41<>"",Q41<>"",R41<>"",S41<>"",T41<>"",U41="pasa",V41="aprobada",OR(X41="",X41="—")),AND(K41="revisada_redireccion",Q41<>"",R41<>"",S41<>"",T41<>"",U41="pasa",V41="aprobada",OR(X41="",X41="—"))),"SÍ","NO") -> NO
...

Sheet Plan relaciones
A1: Atlas 2.0 · plan de las 588 relaciones | B1: Atlas 2.0 · plan de las 588 relaciones | C1: Atlas 2.0 · plan de las 588 relaciones | D1: Atlas 2.0 · plan de las 588 relaciones | E1: Atlas 2.0 · plan de las 588 relaciones | F1: Atlas 2.0 · plan de las 588 relaciones | G1: Atlas 2.0 · plan de las 588 relaciones | H1: Atlas 2.0 · plan de las 588 relaciones | I1: Atlas 2.0 · plan de las 588 relaciones | J1: Atlas 2.0 · plan de las 588 relaciones | K1: Atlas 2.0 · plan de las 588 relaciones | L1: Atlas 2.0 · plan de las 588 relaciones | M1: Atlas 2.0 · plan de las 588 relaciones | N1: Atlas 2.0 · plan de las 588 relaciones | O1: Atlas 2.0 · plan de las 588 relaciones | P1: Atlas 2.0 · plan de las 588 relaciones | Q1: Atlas 2.0 · plan de las 588 relaciones | R1: Atlas 2.0 · plan de las 588 relaciones | S1: Atlas 2.0 · plan de las 588 relaciones | T1: Atlas 2.0 · plan de las 588 relaciones | U1: Atlas 2.0 · plan de las 588 relaciones
A2: Cada relación recibe un estado explícito y se revisa en el lote en que ambos extremos ya están disponibles. Fricción y cruce lingüístico son campos distintos. | B2: Cada relación recibe un estado explícito y se revisa en el lote en que ambos extremos ya están disponibles. Fricción y cruce lingüístico son campos distintos. | C2: Cada relación recibe un estado explícito y se revisa en el lote en que ambos extremos ya están disponibles. Fricción y cruce lingüístico son campos distintos. | D2: Cada relación recibe un estado explícito y se revisa en el lote en que ambos extremos ya están disponibles. Fricción y cruce lingüístico son campos distintos. | E2: Cada relación recibe un estado explícito y se revisa en el lote en que ambos extremos ya están disponibles. Fricción y cruce lingüístico son campos distintos. | F2: Cada relación recibe un estado explícito y se revisa en el lote en que ambos extremos ya están disponibles. Fricción y cruce lingüístico son campos distintos. | G2: Cada relación recibe un estado explícito y se revisa en el lote en que ambos extremos ya están disponibles. Fricción y cruce lingüístico son campos distintos. | H2: Cada relación recibe un estado explícito y se revisa en el lote en que ambos extremos ya están disponibles. Fricción y cruce lingüístico son campos distintos. | I2: Cada relación recibe un estado explícito y se revisa en el lote en que ambos extremos ya están disponibles. Fricción y cruce lingüístico son campos distintos. | J2: Cada relación recibe un estado explícito y se revisa en el lote en que ambos extremos ya están disponibles. Fricción y cruce lingüístico son campos distintos. | K2: Cada relación recibe un estado explícito y se revisa en el lote en que ambos extremos ya están disponibles. Fricción y cruce lingüístico son campos distintos. | L2: Cada relación recibe un estado explícito y se revisa en el lote en que ambos extremos ya están disponibles. Fricción y cruce lingüístico son campos distintos. | M2: Cada relación recibe un estado explícito y se revisa en el lote en que ambos extremos ya están disponibles. Fricción y cruce lingüístico son campos distintos. | N2: Cada relación recibe un estado explícito y se revisa en el lote en que ambos extremos ya están disponibles. Fricción y cruce lingüístico son campos distintos. | O2: Cada relación recibe un estado explícito y se revisa en el lote en que ambos extremos ya están disponibles. Fricción y cruce lingüístico son campos distintos. | P2: Cada relación recibe un estado explícito y se revisa en el lote en que ambos extremos ya están disponibles. Fricción y cruce lingüístico son campos distintos. | Q2: Cada relación recibe un estado explícito y se revisa en el lote en que ambos extremos ya están disponibles. Fricción y cruce lingüístico son campos distintos. | R2: Cada relación recibe un estado explícito y se revisa en el lote en que ambos extremos ya están disponibles. Fricción y cruce lingüístico son campos distintos. | S2: Cada relación recibe un estado explícito y se revisa en el lote en que ambos extremos ya están disponibles. Fricción y cruce lingüístico son campos distintos. | T2: Cada relación recibe un estado explícito y se revisa en el lote en que ambos extremos ya están disponibles. Fricción y cruce lingüístico son campos distintos. | U2: Cada relación recibe un estado explícito y se revisa en el lote en que ambos extremos ya están disponibles. Fricción y cruce lingüístico son campos distintos.
A4: Relación | B4: a heredado | C4: b heredado | D4: a migrado | E4: b migrado | F4: Tipo heredado | G4: Fuente heredada | H4: Estado fuente 1.15 | I4: Decisión piloto | J4: Estado inicial 2.0 | K4: Lote a | L4: Lote b | M4: Alcance | N4: Lote de revisión | O4: Fricción | P4: Cruce lingüístico | Q4: Fuente / páginas 2.0 | R4: Estado revisión | S4: QA técnico | T4: Aprobación | U4: Lista para generar
A5: R0001 | B5: mintz | C5: trouillot | D5: mintz | E5: trouillot | F5: resonancia | G5: Por corroborar. | H5: por_corroborar | J5: por_corroborar | K5: P00 | L5: C04 | M5: frontera | N5: C04 | O5: pendiente | P5: pendiente | R5: sin_iniciar | S5: pendiente | T5: pendiente | U5: =IF(AND(R5="revisada",S5="pasa",T5="aprobada",O5<>"pendiente",P5<>"pendiente",OR(J5="por_corroborar",AND(J5="corroborada",Q5<>""))),"SÍ","NO") -> NO
A6: R0002 | B6: trouillot | C6: casimir | D6: trouillot | E6: casimir | F6: resonancia | G6: Comparten el fenómeno Colonialidad. Por corroborar el vínculo directo. | H6: por_corroborar | J6: por_corroborar | K6: C04 | L6: C01 | M6: frontera | N6: C04 | O6: pendiente | P6: pendiente | R6: sin_iniciar | S6: pendiente | T6: pendiente | U6: =IF(AND(R6="revisada",S6="pasa",T6="aprobada",O6<>"pendiente",P6<>"pendiente",OR(J6="por_corroborar",AND(J6="corroborada",Q6<>""))),"SÍ","NO") -> NO
A7: R0003 | B7: mintz | C7: ortiz | D7: mintz | E7: ortiz | F7: disonancia | G7: Economía política anglófona (Mintz) frente a transculturación cultural hispana (Ortiz): tensión de énfasis. | H7: corroborada | J7: corroborada | K7: P00 | L7: S01 | M7: frontera | N7: S01 | O7: pendiente | P7: pendiente | R7: sin_iniciar | S7: pendiente | T7: pendiente | U7: =IF(AND(R7="revisada",S7="pasa",T7="aprobada",O7<>"pendiente",P7<>"pendiente",OR(J7="por_corroborar",AND(J7="corroborada",Q7<>""))),"SÍ","NO") -> NO
A8: R0004 | B8: ortiz | C8: glissant | D8: ortiz | E8: glissant | F8: resonancia | G8: Comparten el fenómeno Creolización / oralitura. Por corroborar el vínculo directo. | H8: por_corroborar | J8: por_corroborar | K8: S01 | L8: S01 | M8: interna | N8: S01 | O8: pendiente | P8: pendiente | R8: sin_iniciar | S8: pendiente | T8: pendiente | U8: =IF(AND(R8="revisada",S8="pasa",T8="aprobada",O8<>"pendiente",P8<>"pendiente",OR(J8="por_corroborar",AND(J8="corroborada",Q8<>""))),"SÍ","NO") -> NO
A9: R0005 | B9: glissant | C9: brathwaite | D9: glissant | E9: brathwaite | F9: resonancia | G9: Comparten el fenómeno Creolización / oralitura. Por corroborar el vínculo directo. | H9: por_corroborar | J9: por_corroborar | K9: S01 | L9: S01 | M9: interna | N9: S01 | O9: pendiente | P9: pendiente | R9: sin_iniciar | S9: pendiente | T9: pendiente | U9: =IF(AND(R9="revisada",S9="pasa",T9="aprobada",O9<>"pendiente",P9<>"pendiente",OR(J9="por_corroborar",AND(J9="corroborada",Q9<>""))),"SÍ","NO") -> NO
A10: R0006 | B10: glissant | C10: creolite | D10: glissant | E10: creolite | F10: disonancia | G10: La créolité de Bernabé, Chamoiseau y Confiant se distancia de la poética de la Relación de Glissant. | H10: corroborada | J10: corroborada | K10: S01 | L10: A03 | M10: frontera | N10: A03 | O10: pendiente | P10: pendiente | R10: sin_iniciar | S10: pendiente | T10: pendiente | U10: =IF(AND(R10="revisada",S10="pasa",T10="aprobada",O10<>"pendiente",P10<>"pendiente",OR(J10="por_corroborar",AND(J10="corroborada",Q10<>""))),"SÍ","NO") -> NO
A11: R0007 | B11: price | C11: fouchard | D11: price | E11: fouchard | F11: resonancia | G11: Comparten el fenómeno Cimarronaje / fuga. Por corroborar el vínculo directo. | H11: por_corroborar | J11: por_corroborar | K11: P00 | L11: B01 | M11: frontera | N11: B01 | O11: pendiente | P11: pendiente | R11: sin_iniciar | S11: pendiente | T11: pendiente | U11: =IF(AND(R11="revisada",S11="pasa",T11="aprobada",O11<>"pendiente",P11<>"pendiente",OR(J11="por_corroborar",AND(J11="corroborada",Q11<>""))),"SÍ","NO") -> NO
A12: R0008 | B12: price | C12: totumo | D12: price | E12: totumo | F12: disonancia | G12: Comparatismo académico del cimarronaje (Price) frente a la memoria local palenquera del Totumo. | H12: corroborada | I12: degradar_a_por_corroborar | J12: por_corroborar | K12: P00 | L12: P00 | M12: interna | N12: P00 | O12: no | P12: sí | R12: revisada | S12: pasa | T12: aprobada | U12: =IF(AND(R12="revisada",S12="pasa",T12="aprobada",O12<>"pendiente",P12<>"pendiente",OR(J12="por_corroborar",AND(J12="corroborada",Q12<>""))),"SÍ","NO") -> SÍ
A13: R0009 | B13: fouchard | C13: casimir | D13: fouchard | E13: casimir | F13: resonancia | G13: Por corroborar. | H13: por_corroborar | J13: por_corroborar | K13: B01 | L13: C01 | M13: frontera | N13: C01 | O13: pendiente | P13: pendiente | R13: sin_iniciar | S13: pendiente | T13: pendiente | U13: =IF(AND(R13="revisada",S13="pasa",T13="aprobada",O13<>"pendiente",P13<>"pendiente",OR(J13="por_corroborar",AND(J13="corroborada",Q13<>""))),"SÍ","NO") -> NO
A14: R0010 | B14: fouchard | C14: roberts | D14: fouchard | E14: roberts | F14: resonancia | G14: Comparten el fenómeno Cimarronaje / fuga. Por corroborar el vínculo directo. | H14: por_corroborar | J14: por_corroborar | K14: B01 | L14: B01 | M14: interna | N14: B01 | O14: pendiente | P14: pendiente | R14: sin_iniciar | S14: pendiente | T14: pendiente | U14: =IF(AND(R14="revisada",S14="pasa",T14="aprobada",O14<>"pendiente",P14<>"pendiente",OR(J14="por_corroborar",AND(J14="corroborada",Q14<>""))),"SÍ","NO") -> NO
A15: R0011 | B15: roberts | C15: quintero | D15: roberts | E15: quintero | F15: resonancia | G15: Comparten el fenómeno Cimarronaje / fuga. Por corroborar el vínculo directo. | H15: por_corroborar | J15: por_corroborar | K15: B01 | L15: B03 | M15: frontera | N15: B03 | O15: pendiente | P15: pendiente | R15: sin_iniciar | S15: pendiente | T15: pendiente | U15: =IF(AND(R15="revisada",S15="pasa",T15="aprobada",O15<>"pendiente",P15<>"pendiente",OR(J15="por_corroborar",AND(J15="corroborada",Q15<>""))),"SÍ","NO") -> NO
A16: R0012 | B16: cabrera | C16: tambu | D16: cabrera | E16: tambu | F16: resonancia | G16: Comparten el fenómeno Memoria y espiritualidad. Por corroborar el vínculo directo. | H16: por_corroborar | J16: por_corroborar | K16: B05 | L16: B05 | M16: interna | N16: B05 | O16: pendiente | P16: pendiente | R16: sin_iniciar | S16: pendiente | T16: pendiente | U16: =IF(AND(R16="revisada",S16="pasa",T16="aprobada",O16<>"pendiente",P16<>"pendiente",OR(J16="por_corroborar",AND(J16="corroborada",Q16<>""))),"SÍ","NO") -> NO
A17: R0013 | B17: bonilla | C17: aftershocks | D17: bonilla | E17: aftershocks | F17: resonancia | G17: Comparten el fenómeno Soberanías. Por corroborar el vínculo directo. | H17: por_corroborar | J17: por_corroborar | K17: C02 | L17: B03 | M17: frontera | N17: C02 | O17: pendiente | P17: pendiente | R17: sin_iniciar | S17: pendiente | T17: pendiente | U17: =IF(AND(R17="revisada",S17="pasa",T17="aprobada",O17<>"pendiente",P17<>"pendiente",OR(J17="por_corroborar",AND(J17="corroborada",Q17<>""))),"SÍ","NO") -> NO
A18: R0014 | B18: bonilla | C18: ferdinand | D18: bonilla | E18: ferdinand | F18: resonancia | G18: Comparten el fenómeno Colonialidad. Por corroborar el vínculo directo. | H18: por_corroborar | J18: por_corroborar | K18: C02 | L18: C01 | M18: frontera | N18: C02 | O18: pendiente | P18: pendiente | R18: sin_iniciar | S18: pendiente | T18: pendiente | U18: =IF(AND(R18="revisada",S18="pasa",T18="aprobada",O18<>"pendiente",P18<>"pendiente",OR(J18="por_corroborar",AND(J18="corroborada",Q18<>""))),"SÍ","NO") -> NO
A19: R0015 | B19: ferdinand | C19: beyondsun | D19: ferdinand | E19: beyondsun | F19: resonancia | G19: Comparten el fenómeno Catástrofes climáticas. Por corroborar el vínculo directo. | H19: por_corroborar | J19: por_corroborar | K19: C01 | L19: A02 | M19: frontera | N19: C01 | O19: pendiente | P19: pendiente | R19: sin_iniciar | S19: pendiente | T19: pendiente | U19: =IF(AND(R19="revisada",S19="pasa",T19="aprobada",O19<>"pendiente",P19<>"pendiente",OR(J19="por_corroborar",AND(J19="corroborada",Q19<>""))),"SÍ","NO") -> NO
A20: R0016 | B20: rodney | C20: gudynas | D20: rodney | E20: gudynas | F20: resonancia | G20: Comparten el fenómeno Capitalismo racial. Por corroborar el vínculo directo. | H20: por_corroborar | J20: por_corroborar | K20: DE01 | L20: A02 | M20: frontera | N20: DE01 | O20: pendiente | P20: pendiente | R20: sin_iniciar | S20: pendiente | T20: pendiente | U20: =IF(AND(R20="revisada",S20="pasa",T20="aprobada",O20<>"pendiente",P20<>"pendiente",OR(J20="por_corroborar",AND(J20="corroborada",Q20<>""))),"SÍ","NO") -> NO
A21: R0017 | B21: rodney | C21: casimir | D21: rodney | E21: casimir | F21: resonancia | G21: Comparten el fenómeno Colonialidad. Por corroborar el vínculo directo. | H21: por_corroborar | J21: por_corroborar | K21: DE01 | L21: C01 | M21: frontera | N21: DE01 | O21: pendiente | P21: pendiente | R21: sin_iniciar | S21: pendiente | T21: pendiente | U21: =IF(AND(R21="revisada",S21="pasa",T21="aprobada",O21<>"pendiente",P21<>"pendiente",OR(J21="por_corroborar",AND(J21="corroborada",Q21<>""))),"SÍ","NO") -> NO
A22: R0018 | B22: lindskoog | C22: bonilla | D22: lindskoog | E22: bonilla | F22: resonancia | G22: Comparten el fenómeno Soberanías. Por corroborar el vínculo directo. | H22: por_corroborar | J22: por_corroborar | K22: A03 | L22: C02 | M22: frontera | N22: C02 | O22: pendiente | P22: pendiente | R22: sin_iniciar | S22: pendiente | T22: pendiente | U22: =IF(AND(R22="revisada",S22="pasa",T22="aprobada",O22<>"pendiente",P22<>"pendiente",OR(J22="por_corroborar",AND(J22="corroborada",Q22<>""))),"SÍ","NO") -> NO
A23: R0019 | B23: chande | C23: vete | D23: chande | E23: vete | F23: resonancia | G23: Comparten el fenómeno Creolización / oralitura. Por corroborar el vínculo directo. | H23: por_corroborar | J23: por_corroborar | K23: P00 | L23: B04 | M23: frontera | N23: B04 | O23: pendiente | P23: pendiente | R23: sin_iniciar | S23: pendiente | T23: pendiente | U23: =IF(AND(R23="revisada",S23="pasa",T23="aprobada",O23<>"pendiente",P23<>"pendiente",OR(J23="por_corroborar",AND(J23="corroborada",Q23<>""))),"SÍ","NO") -> NO
A24: R0020 | B24: esquiva | C24: rodney | D24: esquiva | E24: rodney | F24: resonancia | G24: Comparten el fenómeno Capitalismo racial. Por corroborar el vínculo directo. | H24: por_corroborar | J24: por_corroborar | K24: S01 | L24: DE01 | M24: frontera | N24: DE01 | O24: pendiente | P24: pendiente | R24: sin_iniciar | S24: pendiente | T24: pendiente | U24: =IF(AND(R24="revisada",S24="pasa",T24="aprobada",O24<>"pendiente",P24<>"pendiente",OR(J24="por_corroborar",AND(J24="corroborada",Q24<>""))),"SÍ","NO") -> NO
... A424: R0420 | B424: garciapenaborders | C424: prestolmasacre | D424: garciapenaborders | E424: prestolmasacre | F424: resonancia | G424: Cita el libro por su título exacto: «un testimonio El masacre se pasa a pie by Freddy Prestol Castillo (Santo Domingo, 1973)». | H424: corroborada | J424: corroborada | K424: C03 | L424: A03 | M424: frontera | N424: C03 | O424: pendiente | P424: pendiente | R424: sin_iniciar | S424: pendiente | T424: pendiente | U424: =IF(AND(R424="revisada",S424="pasa",T424="aprobada",O424<>"pendiente",P424<>"pendiente",OR(J424="por_corroborar",AND(J424="corroborada",Q424<>""))),"SÍ","NO") -> NO
A425: R0421 | B425: stewardpuertorico | C425: mintz | D425: steward | E425: mintz | F425: resonancia | G425: Coautoría directa: Sidney W. Mintz figura como investigador del mismo proyecto («Dr. Sidney W. Mintz, then of Columbia University»), no como cita externa. | H425: corroborada | I425: redirigir_extremo_y_conservar | J425: corroborada | K425: P00 | L425: P00 | M425: interna | N425: P00 | O425: no | P425: no | Q425: Coautoría directa de Sidney W. Mintz en el proyecto The People of Puerto Rico. | R425: revisada | S425: pasa | T425: aprobada | U425: =IF(AND(R425="revisada",S425="pasa",T425="aprobada",O425<>"pendiente",P425<>"pendiente",OR(J425="por_corroborar",AND(J425="corroborada",Q425<>""))),"SÍ","NO") -> SÍ
A426: R0422 | B426: mitchellalibi | C426: robinsonmarxismo | D426: mitchellalibi | E426: robinsonmarxismo | F426: resonancia | G426: Cita el libro por su título original en inglés como autoridad: «Cedric Robinson, Black Marxism: The Making of the Black Radical Tradition», mismo texto catalogado en su edición en español. | H426: corroborada | J426: corroborada | K426: DE01 | L426: DE01 | M426: interna | N426: DE01 | O426: pendiente | P426: pendiente | R426: sin_iniciar | S426: pendiente | T426: pendiente | U426: =IF(AND(R426="revisada",S426="pasa",T426="aprobada",O426<>"pendiente",P426<>"pendiente",OR(J426="por_corroborar",AND(J426="corroborada",Q426<>""))),"SÍ","NO") -> NO
